Workbook

Sheet RP운용
R5: (단위) 수량 : 억 / Delta : 백만원
B7: 구분 | E7: 0.25Y | F7: 0.5Y | G7: 1Y | H7: 1.5Y | I7: 2Y | J7: 2.5Y | K7: 3Y | L7: 5Y | M7: 10Y | N7: 20Y | O7: 30Y | P7: 소계 | Q7: 헷지 전 Dur. | R7: 헷지 후 Dur. | T7: 주요 거래 내역
B8: RP운용 | C8: 일반 RP (증금 RP포함) | D8: 국고/통안 | F8: 1000 | O8: -500 | P8: =SUM(F8:O8) -> 500 | Q8: =P18/P16*100 -> 1.5454545 | R8: =P26/P16*100 -> 0.5
F9: (-100) | O9: (+50) | P9: (-50)
D10: 특수채 | G10: 5000 | H10: 2000 | K10: 1500 | M10: 2000 | P10: =SUM(F10:O10) -> 10500
G11: (-300) | H11: (+200) | P11: (-100)
D12: 은행채 | F12: 2500 | I12: 2500 | J12: 500 | P12: =SUM(F12:O12) -> 5500
D14: 여전채
D16: 현물 소계 | F16: =SUM(F8:F14) -> 3500 | G16: =SUM(G8:G14) -> 5000 | H16: =SUM(H8:H14) -> 2000 | I16: =SUM(I8:I14) -> 2500 | J16: =SUM(J8:J14) -> 500 | K16: =SUM(K8:K14) -> 1500 | L16: =SUM(L8:L14) -> 0 | M16: =SUM(M8:M14) -> 2000 | ... O16: =SUM(O8:O14) -> -500 | P16: =SUM(F16:O16) -> 16500
F17: (-100) | G17: (-300) | H17: (+200) | O17: (+50) | P17: (-150)
D18: 현물 Delta | F18: =F16*0.5/100 -> 17.5 | G18: =G16*1/100 -> 50 | H18: =H16*1.5/100 -> 30 | I18: =I16*2/100 -> 50 | J18: =J16*2.5/100 -> 12.5 | K18: =K16*3/100 -> 45 | L18: =L16*5/100 -> 0 | M18: =M16*10/100 -> 200 | N18: =N16*20/100 -> 0 | O18: =O16*30/100 -> -150 | P18: =SUM(F18:O18) -> 255
D19: 선물 3Y | K19: -1000 | P19: =SUM(F19:O19) -> -1000
K20: (+200)
D21: 선물 10Y | M21: -500 | P21: =SUM(F21:O21) -> -500
M22: (-100)
D23: IRS | E23: 5000 | H23: -2000 | I23: -2500 | J23: -500 | P23: =SUM(F23:O23) -> -5000
D25: 파생 Delta | E25: =E23*0.25/100 -> 12.5 | F25: =F23*0.25/100 -> 0 | G25: =G23*0.25/100 -> 0 | H25: =H23*1.5/100 -> -30 | I25: =I23*2/100 -> -50 | J25: =J23*2.5/100 -> -12.5 | K25: =K19*3/100 -> -30 | L25: =L23*0.25/100 -> 0 | M25: =M21*10/100 -> -50 | N25: =N23*0.25/100 -> 0 | O25: =O23*0.25/100 -> 0 | P25: =SUM(F25:O25) -> -172.5
D26: Delta 합계 | E26: =E18+E25 -> 12.5 | F26: =F18+F25 -> 17.5 | G26: =G18+G25 -> 50 | H26: =H18+H25 -> 0 | I26: =I18+I25 -> 0 | J26: =J18+J25 -> 0 | K26: =K18+K25 -> 15 | L26: =L18+L25 -> 0 | ... P26: =P18+P25 -> 82.5
D28: BS Sp Delta | H28: =H18 -> 30 | I28: =I18 -> 50 | J28: =J18 -> 12.5 | P28: =SUM(E28:O28) -> 92.5
E30: 0.25Y | F30: 0.5Y | G30: 1Y | H30: 1.5Y | I30: 2Y | J30: 2.5Y | K30: 3Y | L30: 5Y | M30: 10Y | N30: 20Y | O30: 30Y | P30: 소계 | Q30: 헷지 전 Dur. | R30: 헷지 후 Dur. | T30: 주요 거래 내역
C31: CMA RP | D31: 국고/통안 | F31: 1000 | O31: -500 | P31: =SUM(F31:O31) -> 500 | Q31: =P41/P39*100 -> 1.5454545 | R31: =P49/P39*100 -> 0.5
F32: (-100) | O32: (+50) | P32: (-50)
D33: 특수채 | G33: 5000 | H33: 2000 | K33: 1500 | M33: 2000 | P33: =SUM(F33:O33) -> 10500
G34: (-300) | H34: (+200) | P34: (-100)
D35: 은행채 | F35: 2500 | I35: 2500 | J35: 500 | P35: =SUM(F35:O35) -> 5500
D37: 여전채
D39: 현물 소계 | F39: =SUM(F31:F37) -> 3500 | G39: =SUM(G31:G37) -> 5000 | H39: =SUM(H31:H37) -> 2000 | I39: =SUM(I31:I37) -> 2500 | J39: =SUM(J31:J37) -> 500 | K39: =SUM(K31:K37) -> 1500 | L39: =SUM(L31:L37) -> 0 | M39: =SUM(M31:M37) -> 2000 | ... O39: =SUM(O31:O37) -> -500 | P39: =SUM(F39:O39) -> 16500
F40: (-100) | G40: (-300) | H40: (+200) | O40: (+50) | P40: (-150)
D41: 현물 Delta | F41: =F39*0.5/100 -> 17.5 | G41: =G39*1/100 -> 50 | H41: =H39*1.5/100 -> 30 | I41: =I39*2/100 -> 50 | J41: =J39*2.5/100 -> 12.5 | K41: =K39*3/100 -> 45 | L41: =L39*5/100 -> 0 | M41: =M39*10/100 -> 200 | N41: =N39*20/100 -> 0 | O41: =O39*30/100 -> -150 | P41: =SUM(F41:O41) -> 255
D42: 선물 3Y | K42: -1000 | P42: =SUM(F42:O42) -> -1000
K43: (+200)
D44: 선물 10Y | M44: -500 | P44: =SUM(F44:O44) -> -500
M45: (-100)
D46: IRS | E46: 5000 | H46: -2000 | I46: -2500 | J46: -500 | P46: =SUM(F46:O46) -> -5000
D48: 파생 Delta | E48: =E46*0.25/100 -> 12.5 | F48: =F46*0.25/100 -> 0 | G48: =G46*0.25/100 -> 0 | H48: =H46*1.5/100 -> -30 | I48: =I46*2/100 -> -50 | J48: =J46*2.5/100 -> -12.5 | K48: =K42*3/100 -> -30 | L48: =L46*0.25/100 -> 0 | M48: =M44*10/100 -> -50 | N48: =N46*0.25/100 -> 0 | O48: =O46*0.25/100 -> 0 | P48: =SUM(F48:O48) -> -172.5
D49: Delta 합계 | E49: =E41+E48 -> 12.5 | F49: =F41+F48 -> 17.5 | G49: =G41+G48 -> 50 | H49: =H41+H48 -> 0 | I49: =I41+I48 -> 0 | J49: =J41+J48 -> 0 | K49: =K41+K48 -> 15 | L49: =L41+L48 -> 0 | ... P49: =P41+P48 -> 82.5
D51: BS Sp Delta | H51: =H41 -> 30 | I51: =I41 -> 50 | J51: =J41 -> 12.5 | P51: =SUM(E51:O51) -> 92.5
E53: 0.25Y | F53: 0.5Y | G53: 1Y | H53: 1.5Y | I53: 2Y | J53: 2.5Y | K53: 3Y | L53: 5Y | M53: 10Y | N53: 20Y | O53: 30Y | P53: 소계 | Q53: 헷지 전 Dur. | R53: 헷지 후 Dur. | T53: 주요 거래 내역
C54: 외화 RP (원화 운용) | D54: 국고/통안 | F54: 1000 | O54: -500 | P54: =SUM(F54:O54) -> 500 | Q54: =P64/P62*100 -> 1.5454545 | R54: =P72/P62*100 -> 0.5
F55: (-100) | O55: (+50) | P55: (-50)
...

Sheet 상품채권운용
S5: (단위) 수량 : 억 / Delta : 백만원
B7: 구분 | F7: 0.25Y | G7: 0.5Y | H7: 1Y | I7: 1.5Y | J7: 2Y | K7: 2.5Y | L7: 3Y | M7: 5Y | N7: 10Y | O7: 20Y | P7: 30Y | Q7: 소계 | R7: 헷지 전 Dur. | S7: 헷지 후 Dur.
B8: 상품채권운용 | C8: 자격북 | D8: PD | E8: 국고/통안 | G8: 1000 | P8: -500 | Q8: =SUM(G8:P8) -> 500 | R8: =Q18/Q16*100 -> 1.5454545 | S8: =Q26/Q16*100 -> 0.5
G9: (-100) | P9: (+50) | Q9: (-50)
E10: 특수채 | H10: 5000 | I10: 2000 | L10: 1500 | N10: 2000 | Q10: =SUM(G10:P10) -> 10500
H11: (-300) | I11: (+200) | Q11: (-100)
E12: 은행채 | G12: 2500 | J12: 2500 | K12: 500 | Q12: =SUM(G12:P12) -> 5500
E14: 여전채
E16: 현물 소계 | G16: =SUM(G8:G14) -> 3500 | H16: =SUM(H8:H14) -> 5000 | I16: =SUM(I8:I14) -> 2000 | J16: =SUM(J8:J14) -> 2500 | K16: =SUM(K8:K14) -> 500 | L16: =SUM(L8:L14) -> 1500 | M16: =SUM(M8:M14) -> 0 | N16: =SUM(N8:N14) -> 2000 | ... P16: =SUM(P8:P14) -> -500 | Q16: =SUM(G16:P16) -> 16500
G17: (-100) | H17: (-300) | I17: (+200) | P17: (+50) | Q17: (-150)
E18: 현물 Delta | G18: =G16*0.5/100 -> 17.5 | H18: =H16*1/100 -> 50 | I18: =I16*1.5/100 -> 30 | J18: =J16*2/100 -> 50 | K18: =K16*2.5/100 -> 12.5 | L18: =L16*3/100 -> 45 | M18: =M16*5/100 -> 0 | N18: =N16*10/100 -> 200 | O18: =O16*20/100 -> 0 | P18: =P16*30/100 -> -150 | Q18: =SUM(G18:P18) -> 255
E19: 선물 3Y | L19: -1000 | Q19: =SUM(G19:P19) -> -1000
L20: (+200)
E21: 선물 10Y | N21: -500 | Q21: =SUM(G21:P21) -> -500
N22: (-100)
E23: IRS | F23: 5000 | I23: -2000 | J23: -2500 | K23: -500 | Q23: =SUM(G23:P23) -> -5000
E25: 파생 Delta | F25: =F23*0.25/100 -> 12.5 | G25: =G23*0.25/100 -> 0 | H25: =H23*0.25/100 -> 0 | I25: =I23*1.5/100 -> -30 | J25: =J23*2/100 -> -50 | K25: =K23*2.5/100 -> -12.5 | L25: =L19*3/100 -> -30 | M25: =M23*0.25/100 -> 0 | N25: =N21*10/100 -> -50 | O25: =O23*0.25/100 -> 0 | P25: =P23*0.25/100 -> 0 | Q25: =SUM(G25:P25) -> -172.5
E26: Delta 합계 | F26: =F18+F25 -> 12.5 | G26: =G18+G25 -> 17.5 | H26: =H18+H25 -> 50 | I26: =I18+I25 -> 0 | J26: =J18+J25 -> 0 | K26: =K18+K25 -> 0 | L26: =L18+L25 -> 15 | M26: =M18+M25 -> 0 | ... Q26: =Q18+Q25 -> 82.5
E28: BS Sp Delta | I28: =I18 -> 30 | J28: =J18 -> 50 | K28: =K18 -> 12.5 | Q28: =SUM(F28:P28) -> 92.5
F30: 0.25Y | G30: 0.5Y | H30: 1Y | I30: 1.5Y | J30: 2Y | K30: 2.5Y | L30: 3Y | M30: 5Y | N30: 10Y | O30: 20Y | P30: 30Y | Q30: 소계 | R30: 헷지 전 Dur. | S30: 헷지 후 Dur.
D31: 소액채권 | E31: 국고/통안 | G31: 1000 | P31: -500 | Q31: =SUM(G31:P31) -> 500 | R31: =Q41/Q39*100 -> 1.5454545 | S31: =Q49/Q39*100 -> 0.5
G32: (-100) | P32: (+50) | Q32: (-50)
E33: 특수채 | H33: 5000 | I33: 2000 | L33: 1500 | N33: 2000 | Q33: =SUM(G33:P33) -> 10500
H34: (-300) | I34: (+200) | Q34: (-100)
E35: 은행채 | G35: 2500 | J35: 2500 | K35: 500 | Q35: =SUM(G35:P35) -> 5500
E37: 여전채
E39: 현물 소계 | G39: =SUM(G31:G37) -> 3500 | H39: =SUM(H31:H37) -> 5000 | I39: =SUM(I31:I37) -> 2000 | J39: =SUM(J31:J37) -> 2500 | K39: =SUM(K31:K37) -> 500 | L39: =SUM(L31:L37) -> 1500 | M39: =SUM(M31:M37) -> 0 | N39: =SUM(N31:N37) -> 2000 | ... P39: =SUM(P31:P37) -> -500 | Q39: =SUM(G39:P39) -> 16500
G40: (-100) | H40: (-300) | I40: (+200) | P40: (+50) | Q40: (-150)
E41: 현물 Delta | G41: =G39*0.5/100 -> 17.5 | H41: =H39*1/100 -> 50 | I41: =I39*1.5/100 -> 30 | J41: =J39*2/100 -> 50 | K41: =K39*2.5/100 -> 12.5 | L41: =L39*3/100 -> 45 | M41: =M39*5/100 -> 0 | N41: =N39*10/100 -> 200 | O41: =O39*20/100 -> 0 | P41: =P39*30/100 -> -150 | Q41: =SUM(G41:P41) -> 255
E42: 선물 3Y | L42: -1000 | Q42: =SUM(G42:P42) -> -1000
L43: (+200)
E44: 선물 10Y | N44: -500 | Q44: =SUM(G44:P44) -> -500
N45: (-100)
E46: IRS | F46: 5000 | I46: -2000 | J46: -2500 | K46: -500 | Q46: =SUM(G46:P46) -> -5000
E48: 파생 Delta | F48: =F46*0.25/100 -> 12.5 | G48: =G46*0.25/100 -> 0 | H48: =H46*0.25/100 -> 0 | I48: =I46*1.5/100 -> -30 | J48: =J46*2/100 -> -50 | K48: =K46*2.5/100 -> -12.5 | L48: =L42*3/100 -> -30 | M48: =M46*0.25/100 -> 0 | N48: =N44*10/100 -> -50 | O48: =O46*0.25/100 -> 0 | P48: =P46*0.25/100 -> 0 | Q48: =SUM(G48:P48) -> -172.5
E49: Delta 합계 | F49: =F41+F48 -> 12.5 | G49: =G41+G48 -> 17.5 | H49: =H41+H48 -> 50 | I49: =I41+I48 -> 0 | J49: =J41+J48 -> 0 | K49: =K41+K48 -> 0 | L49: =L41+L48 -> 15 | M49: =M41+M48 -> 0 | ... Q49: =Q41+Q48 -> 82.5
E51: BS Sp Delta | I51: =I41 -> 30 | J51: =J41 -> 50 | K51: =K41 -> 12.5 | Q51: =SUM(F51:P51) -> 92.5
C53: 일반 Prop | F53: 0.25Y | G53: 0.5Y | H53: 1Y | I53: 1.5Y | J53: 2Y | K53: 2.5Y | L53: 3Y | M53: 5Y | N53: 10Y | O53: 20Y | P53: 30Y | Q53: 소계 | R53: 헷지 전 Dur. | S53: 헷지 후 Dur.
D54: 원화 Prop | E54: 국고/통안 | G54: 1000 | P54: -500 | Q54: =SUM(G54:P54) -> 500 | R54: =Q64/Q62*100 -> 1.5454545 | S54: =Q72/Q62*100 -> 0.5
G55: (-100) | P55: (+50) | Q55: (-50)
...

Sheet 9999
A1: 펀드코드 | B1: 평가일자 | C1: 채권종류 | D1: 종목코드 | E1: 종목명 | F1: 만기일자 | G1: 표면이율 | H1: 수량 | I1: 장부금액 | J1: 평가수익율 | K1: 평가단가 | L1: 평가금액 | M1: 평가손익금액 | N1: 채권이자 | O1: 당기미수이자 | P1: 전기미수이자 | Q1: 경과이자 | R1: 단가구분 | S1: 법인세예수금 | T1: 법인세 | U1: 주민세 | V1: 듀레이션 | W1: 수정듀레이션 | X1: 컨백시티 | Y1: 신용등급 | Z1: KBP단가 | AA1: KBP등급 | AB1: KIS단가 | AC1: KIS등급 | AD1: NICE단가 | AE1: NICE등급 | AF1: 회계구분 | AG1: 이자율구분 | AH1: 매수일자 | AI1: ESG구분 | AJ1: 표준종목코드 | AK1: 발행방법 | AL1: 권리구분
A2: 8001 | B2: 46121 | C2: 국채 | D2: C03501GG3 | E2: 국고채권03500-5603(26-2) | F2: 57049 | G2: 3.5 | H2: 12000000 | I2: 11439899459 | J2: 3.572 | K2: 9897 | L2: 11876400000 | M2: 401120107 | N2: 35380434 | O2: 4279889 | P2: 0 | Q2: 31100545 | S2: 0 | T2: 599170 | U2: 59910 | V2: 18.6415 | W2: 18.3144 | X2: 455.05597 | Z2: 9897.37 | AB2: 9897.37 | AD2: 9897.37 | AF2: 국채 | AG2: 일반채권 | AI2: 해당없음 | AJ2: KR103501GG39 | AK2: 공모채직접발행
A3: 8001 | B3: 46121 | C3: 국채 | D3: L0350C269 | E3: 국고채이자분리채권03290-2609 | F3: 46275 | G3: 3.29 | H3: 432500 | I3: 158924082 | J3: 2.652 | K3: 9890 | L3: 427742500 | M3: -1264441 | N3: 270082859 | O3: 3859441 | P3: 130506186 | Q3: 135717232 | S3: 0 | T3: 18811180 | U3: 1881110 | V3: 0.4201 | W3: 0.41126667 | X3: 0.49243333 | Z3: 9888.45 | AB3: 9891.81 | AD3: 9889.85 | AF3: 국채 | AG3: 일반채권 | AI3: 해당없음 | AJ3: KRC0350C2694 | AK3: 공모채직접발행
A4: 8001 | B4: 46121 | C4: 국채 | D4: L0350C26C | E4: 국고채이자분리채권03580-2612 | F4: 46366 | G4: 3.58 | H4: 1000000 | I4: 406250139 | J4: 2.758 | K4: 9818 | L4: 981800000 | M4: -4410139 | N4: 579960000 | O4: 9710139 | P4: 351224877 | Q4: 219024984 | S4: 0 | T4: 50530860 | U4: 5053060 | V4: 0.6694 | W4: 0.65336667 | X4: 0.99333333 | Z4: 9816.58 | AB4: 9821.15 | AD4: 9819.03 | AF4: 국채 | AG4: 일반채권 | AI4: 해당없음 | AJ4: KRC0350C26C0 | AK4: 공모채직접발행
A5: 8001 | B5: 46121 | C5: 국채 | D5: L0350C273 | E5: 국고채이자분리채권03260-2703 | F5: 46456 | G5: 3.26 | H5: 532500 | I5: 191203391 | J5: 2.903 | K5: 9741 | L5: 518708250 | M5: -1992716 | N5: 329497575 | O5: 4708466 | P5: 160240498 | Q5: 164548611 | S5: 0 | T5: 23092830 | U5: 2309270 | V5: 0.916 | W5: 0.89083333 | X5: 1.6353667 | Z5: 9738.88 | AB5: 9744.79 | AD5: 9739.84 | AF5: 국채 | AG5: 일반채권 | AI5: 해당없음 | AJ5: KRC0350C2736 | AK5: 공모채직접발행
A6: 8001 | B6: 46121 | C6: 국채 | D6: L0350C276 | E6: 국고채이자분리채권03540-2706 | F6: 46548 | G6: 3.54 | H6: 1000000 | I6: 397521650 | J6: 3.009 | K6: 9659 | L6: 965900000 | M6: -5101650 | N6: 573480000 | O6: 9601650 | P6: 347300573 | Q6: 216577777 | S6: 0 | T6: 49966280 | U6: 4996610 | V6: 1.1680333 | W6: 1.1352667 | X6: 2.3462667 | Z6: 9655.03 | AB6: 9664.15 | AD6: 9658.76 | AF6: 국채 | AG6: 일반채권 | AI6: 해당없음 | AJ6: KRC0350C2769 | AK6: 공모채직접발행
A7: 8001 | B7: 46121 | C7: 국채 | D7: L0350C279 | E7: 국고채이자분리채권03560-2709 | F7: 46640 | G7: 3.56 | H7: 532500 | I7: 202664834 | J7: 3.08 | K7: 9577 | L7: 509975250 | M7: -3065012 | N7: 310375428 | O7: 5141762 | P7: 174975540 | Q7: 130258126 | S7: 0 | T7: 25216410 | U7: 2521640 | V7: 1.4201 | W7: 1.3800333 | X7: 3.1665 | Z7: 9577.02 | AB7: 9580.73 | AD7: 9574.76 | AF7: 국채 | AG7: 일반채권 | AI7: 해당없음 | AJ7: KRC0350C2793 | AK7: 공모채직접발행
A8: 8001 | B8: 46121 | C8: 국채 | D8: L0350C283 | E8: 국고채이자분리채권03520-2803 | F8: 46822 | G8: 3.52 | H8: 532500 | I8: 197893926 | J8: 3.203 | K8: 9413 | L8: 501242250 | M8: -3539740 | N8: 306888064 | O8: 5083990 | P8: 173009523 | Q8: 128794551 | S8: 0 | T8: 24933080 | U8: 2493300 | V8: 1.9169 | W8: 1.8573 | X8: 5.2254333 | Z8: 9409.18 | AB8: 9416.52 | AD8: 9415.12 | AF8: 국채 | AG8: 일반채권 | AI8: 해당없음 | AJ8: KRC0350C2835 | AK8: 공모채직접발행
A9: 8001 | B9: 46121 | C9: 국채 | D9: L0350C286 | E9: 국고채이자분리채권03460-2806 | F9: 46914 | G9: 3.46 | H9: 1000000 | I9: 378764662 | J9: 3.252 | K9: 9329 | L9: 932900000 | M9: -6384662 | N9: 560520000 | O9: 9384662 | P9: 339451975 | Q9: 211683363 | S9: 0 | T9: 48837090 | U9: 4883670 | V9: 2.1689667 | W9: 2.1012 | X9: 6.4055 | Z9: 9324.2 | AB9: 9332.24 | AD9: 9331.06 | AF9: 국채 | AG9: 일반채권 | AI9: 해당없음 | AJ9: KRC0350C2868 | AK9: 공모채직접발행
A10: 8001 | B10: 46121 | C10: 국채 | D10: L0350C289 | E10: 국고채이자분리채권01880-2809 | F10: 47006 | G10: 1.88 | H10: 532500 | I10: 388767311 | J10: 3.318 | K10: 9239 | L10: 491976750 | M10: -1810064 | N10: 105019503 | O10: 2715314 | P10: 92404824 | Q10: 9899365 | S10: 0 | T10: 13316810 | U10: 1331660 | V10: 2.421 | W10: 2.3449 | X10: 7.6917333 | Z10: 9239.3 | AB10: 9247.55 | AD10: 9231.49 | AF10: 국채 | AG10: 일반채권 | AI10: 해당없음 | AJ10: KRC0350C2892 | AK10: 공모채직접발행
A11: 8001 | B11: 46121 | C11: 국채 | D11: L0350C293 | E11: 국고채이자분리채권01880-2903 | F11: 47187 | G11: 1.88 | H11: 532500 | I11: 380779811 | J11: 3.414 | K11: 9067 | L11: 482817750 | M11: -2981564 | N11: 105019503 | O11: 2715314 | P11: 92404824 | Q11: 9899365 | S11: 0 | T11: 13316810 | U11: 1331660 | V11: 2.9169 | W11: 2.8205333 | X11: 10.659233 | Z11: 9071.97 | AB11: 9066.34 | AD11: 9063.27 | AF11: 국채 | AG11: 일반채권 | AI11: 해당없음 | AJ11: KRC0350C2934 | AK11: 공모채직접발행
A12: 8001 | B12: 46121 | C12: 국채 | D12: L0350C299 | E12: 국고채이자분리채권01880-2909 | F12: 47371 | G12: 1.88 | H12: 532500 | I12: 371940311 | J12: 3.452 | K12: 8903 | L12: 474084750 | M12: -2875064 | N12: 105019503 | O12: 2715314 | P12: 92404824 | Q12: 9899365 | S12: 0 | T12: 13316810 | U12: 1331660 | V12: 3.421 | W12: 3.3086333 | X12: 14.069133 | Z12: 8904.92 | AB12: 8902.27 | AD12: 8902.27 | AF12: 국채 | AG12: 일반채권 | AI12: 해당없음 | AJ12: KRC0350C2991 | AK12: 공모채직접발행
A13: 8001 | B13: 46121 | C13: 국채 | D13: L0350C29C | E13: 국고채이자분리채권03350-2912 | F13: 47462 | G13: 3.35 | H13: 1000000 | I13: 348886305 | J13: 3.468 | K13: 8823 | L13: 882300000 | M13: -9286305 | N13: 542700000 | O13: 9086305 | P13: 328660149 | Q13: 204953546 | S13: 0 | T13: 47284470 | U13: 4728410 | V13: 3.6703 | W13: 3.5488667 | X13: 15.9559 | Z13: 8821.36 | AB13: 8824.81 | AD13: 8823.55 | AF13: 국채 | AG13: 일반채권 | AI13: 해당없음 | AJ13: KRC0350C29C4 | AK13: 공모채직접발행
... A947: 8009 | B947: 46121 | C947: 국채 | D947: C03502GB3 | E947: 국고채권01875-5103(21-2) | F947: 55222 | G947: 1.875 | H947: 130000000 | I947: 98559122930 | J947: 3.599 | K947: 7194 | L947: 93522000000 | M947: -5242455805 | N947: 205332875 | O947: 205332875 | P947: 0 | Q947: 0 | S947: 0 | T947: 28746570 | U947: 2874620 | V947: 18.882033 | W947: 18.548267 | X947: 420.7033 | Z947: 7193.56 | AB947: 7197.56 | AD947: 7193.56 | AF947: 국채 | AG947: 일반채권 | AI947: 해당없음 | AJ947: KR103502GB33 | AK947: 공모채직접발행
A948: 8010 | B948: 46121 | C948: 금융채 | D948: B000011E9 | E948: 신한은행28-09-이-2-A | F948: 46270 | G948: 3.3 | H948: 10000000 | I948: 10030250000 | J948: 2.84 | K948: 10050 | L948: 10050000000 | M948: -12532608 | N948: 32282608 | O948: 32282608 | P948: 0 | Q948: 0 | S948: 0 | T948: 4519560 | U948: 451950 | V948: 0.40116667 | W948: 0.39833333 | X948: 0.2532 | Y948: AAA | Z948: 10050.76 | AA948: AAA | AB948: 10050.52 | AC948: AAA | AD948: 10050.12 | AE948: AAA | AF948: 금융채 | AG948: 일반채권 | AI948: 해당없음 | AJ948: KR6000011E97 | AK948: 공모채간접발행
A949: 8010 | B949: 46121 | C949: 금융채 | D949: B000011EB | E949: 신한은행28-11-이-2-A | F949: 46330 | G949: 3.24 | H949: 20000000 | I949: 20067869566 | J949: 2.888 | K949: 10078 | L949: 20156000000 | M949: -30184172 | N949: 118314606 | O949: 118314606 | P949: 0 | Q949: 0 | S949: 0 | T949: 16564040 | U949: 1656400 | V949: 0.56246667 | W949: 0.55843333 | X949: 0.44883333 | Y949: AAA | Z949: 10079.12 | AA949: AAA | AB949: 10078.9 | AC949: AAA | AD949: 10078.28 | AE949: AAA | AF949: 금융채 | AG949: 일반채권 | AI949: 해당없음 | AJ949: KR6000011EB7 | AK949: 공모채간접발행
A950: 8010 | B950: 46121 | C950: 금융채 | D950: B000013F4 | E950: 신한은행29-04-이-1-B | F950: 46135 | G950: 2.59 | H950: 10000000 | I950: 9992733696 | J950: 2.744 | K950: 10054 | L950: 10054000000 | M950: 5869082 | N950: 55397222 | O950: 55397222 | P950: 0 | Q950: 0 | S950: 0 | T950: 7755610 | U950: 775560 | V950: 0.0371 | W950: 0.036866667 | X950: 0.0079666666 | Y950: AAA | Z950: 10054.79 | AA950: AAA | AB950: 10054.79 | AC950: AAA | AD950: 10054.75 | AE950: AAA | AF950: 금융채 | AG950: 일반채권 | AI950: 해당없음 | AJ950: KR6000013F45 | AK950: 공모채간접발행
A951: 8010 | B951: 46121 | C951: 금융채 | D951: B000018E8 | E951: 신한은행28-08-이-2-A | F951: 46256 | G951: 3.26 | H951: 10000000 | I951: 10026565218 | J951: 2.829 | K951: 10058 | L951: 10058000000 | M951: -11604543 | N951: 43039325 | O951: 43039325 | P951: 0 | Q951: 0 | S951: 0 | T951: 6025500 | U951: 602550 | V951: 0.36706667 | W951: 0.36446667 | X951: 0.21866667 | Y951: AAA | Z951: 10058.88 | AA951: AAA | AB951: 10058.66 | AC951: AAA | AD951: 10058.29 | AE951: AAA | AF951: 금융채 | AG951: 일반채권 | AI951: 해당없음 | AJ951: KR6000018E82 | AK951: 공모채간접발행
A952: 8010 | B952: 46121 | C952: 금융채 | D952: B000018E9 | E952: 신한은행28-09-이-2-C | F952: 46277 | G952: 3.2 | H952: 10000000 | I952: 10025222223 | J952: 2.845 | K952: 10039 | L952: 10039000000 | M952: -11439614 | N952: 25217391 | O952: 25217391 | P952: 0 | Q952: 0 | S952: 0 | T952: 3530430 | U952: 353040 | V952: 0.42023333 | W952: 0.41726667 | X952: 0.27376667 | Y952: AAA | Z952: 10040.2 | AA952: AAA | AB952: 10039.95 | AC952: AAA | AD952: 10039.49 | AE952: AAA | AF952: 금융채 | AG952: 일반채권 | AI952: 해당없음 | AJ952: KR6000018E90 | AK952: 공모채간접발행
A953: 8010 | B953: 46121 | C953: 금융채 | D953: B000019EB | E953: 신한은행28-11-이-2-C | F953: 46355 | G953: 3.04 | H953: 30000000 | I953: 30058318682 | J953: 2.908 | K953: 10042 | L953: 30126000000 | M953: -36185348 | N953: 103866666 | O953: 103866666 | P953: 0 | Q953: 0 | S953: 0 | T953: 14541330 | U953: 1454130 | V953: 0.63153333 | W953: 0.627 | X953: 0.54593333 | Y953: AAA | Z953: 10043.09 | AA953: AAA | AB953: 10042.96 | AC953: AAA | AD953: 10042.27 | AE953: AAA | AF953: 금융채 | AG953: 일반채권 | AI953: 해당없음 | AJ953: KR6000019EB0 | AK953: 공모채간접발행
A954: 8010 | B954: 46121 | C954: 금융채 | D954: B000031EB | E954: 우리은행28-11-이표02-갑-11 | F954: 46337 | G954: 3.19 | H954: 50000000 | I954: 50153953805 | J954: 2.894 | K954: 10069 | L954: 50345000000 | M954: -68813355 | N954: 259859550 | O954: 259859550 | P954: 0 | Q954: 0 | S954: 0 | T954: 36380330 | U954: 3638030 | V954: 0.58226667 | W954: 0.57806667 | X954: 0.47536667 | Y954: AAA | Z954: 10069.36 | AA954: AAA | AB954: 10069.13 | AC954: AAA | AD954: 10068.55 | AE954: AAA | AF954: 금융채 | AG954: 일반채권 | AI954: 해당없음 | AJ954: KR6000031EB5 | AK954: 공모채간접발행
A955: 8010 | B955: 46121 | C955: 금융채 | D955: B000034E8 | E955: 우리은행28-08-이표02-갑-22 | F955: 46256 | G955: 3.26 | H955: 10000000 | I955: 10026565218 | J955: 2.83 | K955: 10058 | L955: 10058000000 | M955: -11604543 | N955: 43039325 | O955: 43039325 | P955: 0 | Q955: 0 | S955: 0 | T955: 6025500 | U955: 602550 | V955: 0.36706667 | W955: 0.36446667 | X955: 0.21866667 | Y955: AAA | Z955: 10058.73 | AA955: AAA | AB955: 10058.66 | AC955: AAA | AD955: 10058.29 | AE955: AAA | AF955: 금융채 | AG955: 일반채권 | AI955: 해당없음 | AJ955: KR6000034E82 | AK955: 공모채간접발행
A956: 8010 | B956: 46121 | C956: 금융채 | D956: B000038EA | E956: 우리은행28-10-이표1.5-갑-25 | F956: 46137 | G956: 3.2 | H956: 20000000 | I956: 20023739132 | J956: 2.748 | K956: 10068 | L956: 20136000000 | M956: -21072464 | N956: 133333332 | O956: 133333332 | P956: 0 | Q956: 0 | S956: 0 | T956: 18666660 | U956: 1866660 | V956: 0.042666667 | W956: 0.042366667 | X956: 0.0094666666 | Y956: AAA | Z956: 10068.47 | AA956: AAA | AB956: 10068.49 | AC956: AAA | AD956: 10068.45 | AE956: AAA | AF956: 금융채 | AG956: 일반채권 | AI956: 해당없음 | AJ956: KR6000038EA2 | AK956: 공모채간접발행
A957: 8010 | B957: 46121 | C957: 금융채 | D957: B004941E5 | E957: 하나은행47-05-이2갑-02 | F957: 46144 | G957: 3.71 | H957: 10000000 | I957: 10029478261 | J957: 2.749 | K957: 10075 | L957: 10075000000 | M957: -24338935 | N957: 69860674 | O957: 69860674 | P957: 0 | Q957: 0 | S957: 0 | T957: 9780490 | U957: 978040 | V957: 0.062833333 | W957: 0.062433333 | X957: 0.015566667 | Y957: AAA | Z957: 10075.68 | AA957: AAA | AB957: 10075.62 | AC957: AAA | AD957: 10075.58 | AE957: AAA | AF957: 금융채 | AG957: 일반채권 | AI957: 해당없음 | AJ957: KR6004941E52 | AK957: 공모채간접발행
A958: 8010 | B958: 46121 | C958: 금융채 | D958: B004941F5 | E958: 하나은행48-05이1.5갑-02 | F958: 46328 | G958: 2.55 | H958: 10000000 | I958: 9976391305 | J958: 2.886 | K958: 10029 | L958: 10029000000 | M958: 4579482 | N958: 48029213 | O958: 48029213 | P958: 0 | Q958: 0 | S958: 0 | T958: 6724080 | U958: 672400 | V958: 0.55813333 | W958: 0.5541 | X958: 0.44266667 | Y958: AAA | Z958: 10029.57 | AA958: AAA | AB958: 10029.29 | AC958: AAA | AD958: 10028.74 | AE958: AAA | AF958: 금융채 | AG958: 일반채권 | AI958: 해당없음 | AJ958: KR6004941F51 | AK958: 공모채간접발행
A959: 8010 | B959: 46121 | C959: 금융채 | D959: B004941F6 | E959: 하나은행48-06이1.5갑-02 | F959: 46358 | G959: 2.52 | H959: 10000000 | I959: 9972000000 | J959: 2.91 | K959: 10001 | L959: 10001000000 | M959: 2293479 | N959: 26706521 | O959: 26706521 | P959: 0 | Q959: 0 | S959: 0 | T959: 3738910 | U959: 373890 | V959: 0.64036667 | W959: 0.63576667 | X959: 0.55886667 | Y959: AAA | Z959: 10002.11 | AA959: AAA | AB959: 10001.85 | AC959: AAA | AD959: 10001.28 | AE959: AAA | AF959: 금융채 | AG959: 일반채권 | AI959: 해당없음 | AJ959: KR6004941F69 | AK959: 공모채간접발행
... A965: 8010 | B965: 46121 | C965: 금융채 | D965: B060006EB | E965: 국민은행4411이표일(03)2-28 | F965: 46354 | G965: 3.11 | H965: 60000000 | I965: 60151597828 | J965: 2.907 | K965: 10048 | L965: 60288000000 | M965: -78502322 | N965: 214904494 | O965: 214904494 | P965: 0 | Q965: 0 | S965: 0 | T965: 30086620 | U965: 3008660 | V965: 0.63016667 | W965: 0.6256 | X965: 0.54393333 | Y965: AAA | Z965: 10048.65 | AA965: AAA | AB965: 10048.53 | AC965: AAA | AD965: 10047.9 | AE965: AAA | AF965: 금융채 | AG965: 일반채권 | AI965: 해당없음 | AJ965: KR6060006EB4 | AK965: 공모채간접발행
A966: 8010 | B966: 46121 | C966: 국채 | D966: C03501GF6 | E966: 국고채권02250-2806(25-4) | F966: 46914 | G966: 2.25 | H966: 30000000 | I966: 29485203297 | J966: 3.252 | K966: 9866 | L966: 29598000000 | M966: -111585165 | N966: 224381868 | O966: 183585165 | P966: 40796703 | Q966: 0 | S966: 0 | T966: 31413460 | U966: 3141340 | V966: 2.1133 | W966: 2.0795 | X966: 5.4077667 | Z966: 9866.21 | AB966: 9866.21 | AD966: 9866.21 | AF966: 국채 | AG966: 일반채권 | AI966: 해당없음 | AJ966: KR103501GF63 | AK966: 공모채직접발행
A967: 8010 | B967: 46121 | C967: 금융채 | D967: E10201GEC | E967: 산업금융채권24신이0200-1202-2 | F967: 46358 | G967: 2.85 | H967: 10000000 | I967: 10004233334 | J967: 2.881 | K967: 10028 | L967: 10028000000 | M967: -6458334 | N967: 30225000 | O967: 30225000 | P967: 0 | Q967: 0 | S967: 0 | T967: 4231500 | U967: 423150 | V967: 0.63976667 | W967: 0.6352 | X967: 0.55826667 | Y967: AAA | Z967: 10028.36 | AA967: AAA | AB967: 10028.23 | AC967: AAA | AD967: 10027.59 | AE967: AAA | AF967: 특수채 | AG967: 일반채권 | AI967: 해당없음 | AJ967: KR310201GEC2 | AK967: 공모채간접발행
A968: 8010 | B968: 46121 | C968: 금융채 | D968: E10202GEB | E968: 산업금융채권24신이0106-1104-1 | F968: 46146 | G968: 3.2 | H968: 20000000 | I968: 20027130435 | J968: 2.735 | K968: 10061 | L968: 20122000000 | M968: -21984367 | N968: 116853932 | O968: 116853932 | P968: 0 | Q968: 0 | S968: 0 | T968: 16359550 | U968: 1635950 | V968: 0.068466667 | W968: 0.068 | X968: 0.017466667 | Y968: AAA | Z968: 10061.51 | AA968: AAA | AB968: 10061.42 | AC968: AAA | AD968: 10061.39 | AE968: AAA | AF968: 특수채 | AG968: 일반채권 | AI968: 해당없음 | AJ968: KR310202GEB2 | AK968: 공모채간접발행
A969: 8010 | B969: 46121 | C969: 금융채 | D969: E10204GEC | E969: 산업금융채권24신이0200-1209-1 | F969: 46365 | G969: 2.88 | H969: 10000000 | I969: 10007600000 | J969: 2.887 | K969: 10024 | L969: 10024000000 | M969: -8643478 | N969: 25043478 | O969: 25043478 | P969: 0 | Q969: 0 | S969: 0 | T969: 3506080 | U969: 350600 | V969: 0.65873333 | W969: 0.65403333 | X969: 0.58756667 | Y969: AAA | Z969: 10024.66 | AA969: AAA | AB969: 10024.66 | AC969: AAA | AD969: 10024.07 | AE969: AAA | AF969: 특수채 | AG969: 일반채권 | AI969: 해당없음 | AJ969: KR310204GEC6 | AK969: 공모채간접발행
A970: 8010 | B970: 46121 | C970: 금융채 | D970: E10206GE7 | E970: 산업금융채권24신이0200-0716-1 | F970: 46219 | G970: 3.2 | H970: 20000000 | I970: 20040086957 | J970: 2.778 | K970: 10085 | L970: 20170000000 | M970: -19420290 | N970: 149333333 | O970: 149333333 | P970: 0 | Q970: 0 | S970: 0 | T970: 20906660 | U970: 2090660 | V970: 0.26566667 | W970: 0.26383333 | X970: 0.1343 | Y970: AAA | Z970: 10085.99 | AA970: AAA | AB970: 10085.88 | AC970: AAA | AD970: 10085.54 | AE970: AAA | AF970: 특수채 | AG970: 일반채권 | AI970: 해당없음 | AJ970: KR310206GE71 | AK970: 공모채간접발행
A971: 8010 | B971: 46121 | C971: 금융채 | D971: E10208GD7 | E971: 산업금융채권23신이0300-0725-1 | F971: 46228 | G971: 3.93 | H971: 10000000 | I971: 10062343479 | J971: 2.784 | K971: 10114 | L971: 10114000000 | M971: -30260145 | N971: 81916666 | O971: 81916666 | P971: 0 | Q971: 0 | S971: 0 | T971: 11468330 | U971: 1146830 | V971: 0.29023333 | W971: 0.28823333 | X971: 0.15236667 | Y971: AAA | Z971: 10115.17 | AA971: AAA | AB971: 10115.02 | AC971: AAA | AD971: 10114.64 | AE971: AAA | AF971: 특수채 | AG971: 일반채권 | AI971: 해당없음 | AJ971: KR310208GD70 | AK971: 공모채간접발행
A972: 8010 | B972: 46121 | C972: 금융채 | D972: E10210GD8 | E972: 산업금융채권23신이0300-0822-2 | F972: 46256 | G972: 4.08 | H972: 10000000 | I972: 10080652174 | J972: 2.806 | K972: 10100 | L972: 10100000000 | M972: -34517342 | N972: 53865168 | O972: 53865168 | P972: 0 | Q972: 0 | S972: 0 | T972: 7541120 | U972: 754110 | V972: 0.36656667 | W972: 0.364 | X972: 0.21836667 | Y972: AAA | Z972: 10100.41 | AA972: AAA | AB972: 10100.3 | AC972: AAA | AD972: 10099.82 | AE972: AAA | AF972: 특수채 | AG972: 일반채권 | AI972: 해당없음 | AJ972: KR310210GD84 | AK972: 공모채간접발행
A973: 8010 | B973: 46121 | C973: 금융채 | D973: E10211GB6 | E973: 산업금융채권21신이0500-0614-3 | F973: 46187 | G973: 1.83 | H973: 10000000 | I973: 9955840000 | J973: 2.758 | K973: 9997 | L973: 9997000000 | M973: 27718696 | N973: 13441304 | O973: 13441304 | P973: 0 | Q973: 0 | S973: 0 | T973: 1881780 | U973: 188170 | V973: 0.17763333 | W973: 0.17643333 | X973: 0.0707 | Y973: AAA | Z973: 9997.2 | AA973: AAA | AB973: 9997.04 | AC973: AAA | AD973: 9996.89 | AE973: AAA | AF973: 특수채 | AG973: 일반채권 | AI973: 해당없음 | AJ973: KR310211GB69 | AK973: 공모채간접발행
A974: 8010 | B974: 46121 | C974: 금융채 | D974: E10212GE7 | E974: 산업금융채권24신이0200-0723-1 | F974: 46226 | G974: 3.22 | H974: 10000000 | I974: 10022750000 | J974: 2.782 | K974: 10081 | L974: 10081000000 | M974: -10622222 | N974: 68872222 | O974: 68872222 | P974: 0 | Q974: 0 | S974: 0 | T974: 9642110 | U974: 964210 | V974: 0.2851 | W974: 0.28313333 | X974: 0.1484 | Y974: AAA | Z974: 10081.44 | AA974: AAA | AB974: 10081.3 | AC974: AAA | AD974: 10080.93 | AE974: AAA | AF974: 특수채 | AG974: 일반채권 | AI974: 해당없음 | AJ974: KR310212GE73 | AK974: 공모채간접발행
A975: 8010 | B975: 46121 | C975: 금융채 | D975: E10212GEB | E975: 산업금융채권24신이0200-1115-3 | F975: 46341 | G975: 3.19 | H975: 10000000 | I975: 10033232609 | J975: 2.869 | K975: 10067 | L975: 10067000000 | M975: -14650586 | N975: 48417977 | O975: 48417977 | P975: 0 | Q975: 0 | S975: 0 | T975: 6778510 | U975: 677850 | V975: 0.59346667 | W975: 0.58926667 | X975: 0.49093333 | Y975: AAA | Z975: 10067.46 | AA975: AAA | AB975: 10067.41 | AC975: AAA | AD975: 10066.75 | AE975: AAA | AF975: 특수채 | AG975: 일반채권 | AI975: 해당없음 | AJ975: KR310212GEB1 | AK975: 공모채간접발행
A976: 8010 | B976: 46121 | C976: 금융채 | D976: E10213GE7 | E976: 산업금융채권24신이0206-0724-1 | F976: 46411 | G976: 3.22 | H976: 10000000 | I976: 10043625000 | J976: 2.936 | K976: 10089 | L976: 10089000000 | M976: -22602777 | N976: 67977777 | O976: 67977777 | P976: 0 | Q976: 0 | S976: 0 | T976: 9516880 | U976: 951680 | V976: 0.778 | W976: 0.77233333 | X976: 0.79216667 | Y976: AAA | Z976: 10089.89 | AA976: AAA | AB976: 10090.35 | AC976: AAA | AD976: 10089.65 | AE976: AAA | AF976: 특수채 | AG976: 일반채권 | AI976: 해당없음 | AJ976: KR310213GE72 | AK976: 공모채간접발행
A977: 8010 | B977: 46121 | C977: 금융채 | D977: E10213GEB | E977: 산업금융채권24신이0200-1118-1 | F977: 46344 | G977: 3.18 | H977: 10000000 | I977: 10032978261 | J977: 2.871 | K977: 10063 | L977: 10063000000 | M977: -15534440 | N977: 45556179 | O977: 45556179 | P977: 0 | Q977: 0 | S977: 0 | T977: 6377860 | U977: 637780 | V977: 0.60193333 | W977: 0.59766667 | X977: 0.50286667 | Y977: AAA | Z977: 10064.12 | AA977: AAA | AB977: 10064.12 | AC977: AAA | AD977: 10063.46 | AE977: AAA | AF977: 특수채 | AG977: 일반채권 | AI977: 해당없음 | AJ977: KR310213GEB9 | AK977: 공모채간접발행
A978: 8010 | B978: 46121 | C978: 금융채 | D978: E10216GEB | E978: 산업금융채권24신이0200-1121-1 | F978: 46347 | G978: 3.15 | H978: 10000000 | I978: 10030882609 | J978: 2.874 | K978: 10059 | L978: 10059000000 | M978: -14381485 | N978: 42498876 | O978: 42498876 | P978: 0 | Q978: 0 | S978: 0 | T978: 5949840 | U978: 594980 | V978: 0.6104 | W978: 0.60606667 | X978: 0.515 | Y978: AAA | Z978: 10059.29 | AA978: AAA | AB978: 10059.35 | AC978: AAA | AD978: 10058.68 | AE978: AAA | AF978: 특수채 | AG978: 일반채권 | AI978: 해당없음 | AJ978: KR310216GEB2 | AK978: 공모채간접발행
...

Sheet 9994
A1: 펀드코드 | B1: 평가일자 | C1: 채권종류 | D1: 종목코드 | E1: 종목명 | F1: 만기일자 | G1: 표면이율 | H1: 수량 | I1: 장부금액 | J1: 평가수익율 | K1: 평가단가 | L1: 평가금액 | M1: 평가손익금액 | N1: 채권이자 | O1: 당기미수이자 | P1: 전기미수이자 | Q1: 경과이자 | R1: 단가구분 | S1: 법인세예수금 | T1: 법인세 | U1: 주민세 | V1: 듀레이션 | W1: 수정듀레이션 | X1: 컨백시티 | Y1: 신용등급 | Z1: KBP단가 | AA1: KBP등급 | AB1: KIS단가 | AC1: KIS등급 | AD1: NICE단가 | AE1: NICE등급 | AF1: 회계구분 | AG1: 이자율구분 | AH1: 매수일자 | AI1: ESG구분 | AJ1: 표준종목코드 | AK1: 발행방법 | AL1: 권리구분
A2: 9994 | B2: 46121 | C2: 금융채 | D2: B000019EA | E2: 신한은행28-10-이-3-B | F2: 46684 | G2: 3.24 | H2: 20000000 | I2: 19998000000 | J2: 3.353 | K2: 10051 | L2: 20102000000 | M2: -32800000 | N2: 136800000 | O2: 136800000 | P2: 0 | Q2: 0 | S2: 0 | T2: 19152000 | U2: 1915200 | V2: 1.4982333 | W2: 1.4858 | X2: 2.6160667 | Y2: AAA | Z2: 10052.47 | AA2: AAA | AB2: 10052.02 | AC2: AAA | AD2: 10049.63 | AE2: AAA | AF2: 금융채 | AG2: 일반채권 | AI2: 해당없음 | AJ2: KR6000019EA2 | AK2: 공모채간접발행
A3: 9994 | B3: 46121 | C3: 금융채 | D3: B000032F8 | E3: 우리은행29-08-이1.5-갑25(지) | F3: 46443 | G3: 2.56 | H3: 20000000 | I3: 19999000000 | J3: 3.03 | K3: 9990 | L3: 19980000000 | M3: -82280898 | N3: 63280898 | O3: 63280898 | P3: 0 | Q3: 0 | S3: 0 | T3: 8859320 | U3: 885930 | V3: 0.868 | W3: 0.86143333 | X3: 0.95606667 | Y3: AAA | Z3: 9991.52 | AA3: AAA | AB3: 9991.35 | AC3: AAA | AD3: 9990.06 | AE3: AAA | AF3: 금융채 | AG3: 일반채권 | AI3: 지속가능채권 | AJ3: KR6000032F83 | AK3: 공모채간접발행
A4: 9994 | B4: 46121 | C4: 금융채 | D4: B000032FA | E4: 우리은행29-10-이표02-갑-17 | F4: 46677 | G4: 2.6 | H4: 10000000 | I4: 10000000000 | J4: 3.347 | K4: 9949 | L4: 9949000000 | M4: -110944444 | N4: 59944444 | O4: 59944444 | P4: 0 | Q4: 0 | S4: 0 | T4: 8392220 | U4: 839220 | V4: 1.4866 | W4: 1.4743 | X4: 2.5726 | Y4: AAA | Z4: 9950.71 | AA4: AAA | AB4: 9950.27 | AC4: AAA | AD4: 9947.77 | AE4: AAA | AF4: 금융채 | AG4: 일반채권 | AI4: 해당없음 | AJ4: KR6000032FA2 | AK4: 공모채간접발행
A5: 9994 | B5: 46121 | C5: 금융채 | D5: B000037EA | E5: 우리은행28-10-이표2.5-갑-24 | F5: 46501 | G5: 3.23 | H5: 10000000 | I5: 10000000000 | J5: 3.132 | K5: 10078 | L5: 10078000000 | M5: 9811112 | N5: 68188888 | O5: 68188888 | P5: 0 | Q5: 0 | S5: 0 | T5: 9546440 | U5: 954640 | V5: 1.0200333 | W5: 1.0121333 | X5: 1.2870333 | Y5: AAA | Z5: 10079.3 | AA5: AAA | AB5: 10078.18 | AC5: AAA | AD5: 10076.76 | AE5: AAA | AF5: 금융채 | AG5: 일반채권 | AI5: 해당없음 | AJ5: KR6000037EA4 | AK5: 공모채간접발행
A6: 9994 | B6: 46121 | C6: 금융채 | D6: B004941F5 | E6: 하나은행48-05이1.5갑-02 | F6: 46328 | G6: 2.55 | H6: 20000000 | I6: 19999000000 | J6: 2.886 | K6: 10029 | L6: 20058000000 | M6: -37058426 | N6: 96058426 | O6: 96058426 | P6: 0 | Q6: 0 | S6: 0 | T6: 13448170 | U6: 1344810 | V6: 0.55813333 | W6: 0.5541 | X6: 0.44266667 | Y6: AAA | Z6: 10029.57 | AA6: AAA | AB6: 10029.29 | AC6: AAA | AD6: 10028.74 | AE6: AAA | AF6: 금융채 | AG6: 일반채권 | AI6: 해당없음 | AJ6: KR6004941F51 | AK6: 공모채간접발행
A7: 9994 | B7: 46121 | C7: 금융채 | D7: B004944F3 | E7: 하나은행48-03이3갑-17 | F7: 46829 | G7: 2.84 | H7: 20000000 | I7: 19998000000 | J7: 3.463 | K7: 9902 | L7: 19804000000 | M7: -231043478 | N7: 37043478 | O7: 37043478 | P7: 0 | Q7: 0 | S7: 0 | T7: 5186080 | U7: 518600 | V7: 1.8868333 | W7: 1.8706333 | X7: 4.0170333 | Y7: AAA | Z7: 9902.28 | AA7: AAA | AB7: 9902.47 | AC7: AAA | AD7: 9901.73 | AE7: AAA | AF7: 금융채 | AG7: 일반채권 | AI7: 해당없음 | AJ7: KR6004944F33 | AK7: 공모채간접발행
A8: 9994 | B8: 46121 | C8: 금융채 | D8: B004946F7 | E8: 하나은행48-07이2갑-17 | F8: 46585 | G8: 2.55 | H8: 20000000 | I8: 19999000000 | J8: 3.237 | K8: 9973 | L8: 19946000000 | M8: -170675555 | N8: 117675555 | O8: 117675555 | P8: 0 | Q8: 0 | S8: 0 | T8: 16474570 | U8: 1647450 | V8: 1.2467 | W8: 1.2367 | X8: 1.8555667 | Y8: AAA | Z8: 9974.75 | AA8: AAA | AB8: 9973.89 | AC8: AAA | AD8: 9972.04 | AE8: AAA | AF8: 금융채 | AG8: 일반채권 | AI8: 해당없음 | AJ8: KR6004946F72 | AK8: 공모채간접발행
A9: 9994 | B9: 46121 | C9: 금융채 | D9: B060006F9 | E9: 국민은행4509이표일(03)1.5-26 | F9: 46472 | G9: 2.59 | H9: 10000000 | I9: 10000000000 | J9: 3.087 | K9: 9963 | L9: 9963000000 | M9: -47557065 | N9: 10557065 | O9: 10557065 | P9: 0 | Q9: 0 | S9: 0 | T9: 1477980 | U9: 147790 | V9: 0.9506 | W9: 0.94333333 | X9: 1.1265333 | Y9: AAA | Z9: 9964.62 | AA9: AAA | AB9: 9963.68 | AC9: AAA | AD9: 9962.55 | AE9: AAA | AF9: 금융채 | AG9: 일반채권 | AI9: 해당없음 | AJ9: KR6060006F97 | AK9: 공모채간접발행

Sheet 9992
A1: 펀드코드 | B1: 평가일자 | C1: 채권종류 | D1: 종목코드 | E1: 종목명 | F1: 만기일자 | G1: 표면이율 | H1: 수량 | I1: 장부금액 | J1: 평가수익율 | K1: 평가단가 | L1: 평가금액 | M1: 평가손익금액 | N1: 채권이자 | O1: 당기미수이자 | P1: 전기미수이자 | Q1: 경과이자 | R1: 단가구분 | S1: 법인세예수금 | T1: 법인세 | U1: 주민세 | V1: 듀레이션 | W1: 수정듀레이션 | X1: 컨백시티 | Y1: 신용등급 | Z1: KBP단가 | AA1: KBP등급 | AB1: KIS단가 | AC1: KIS등급 | AD1: NICE단가 | AE1: NICE등급 | AF1: 회계구분 | AG1: 이자율구분 | AH1: 매수일자 | AI1: ESG구분 | AJ1: 표준종목코드 | AK1: 발행방법 | AL1: 권리구분
A2: 8051 | B2: 46121 | C2: 국채 | D2: C03501GG3 | E2: 국고채권03500-5603(26-2) | F2: 57049 | G2: 3.5 | H2: 20000000 | I2: 19892050000 | J2: 3.572 | K2: 9897 | L2: 19794000000 | M2: 98050000 | N2: 0 | O2: 0 | P2: 0 | Q2: 0 | S2: 0 | T2: 0 | U2: 0 | V2: 18.6415 | W2: 18.3144 | X2: 455.05597 | Z2: 9897.37 | AB2: 9897.37 | AD2: 9897.37 | AF2: 국채 | AG2: 일반채권 | AI2: 해당없음 | AJ2: KR103501GG39 | AK2: 공모채직접발행

Sheet 7120(원화)
A1: 펀드코드 | B1: 평가일자 | C1: 채권종류 | D1: 종목코드 | E1: 종목명 | F1: 만기일자 | G1: 표면이율 | H1: 수량 | I1: 장부금액 | J1: 평가수익율 | K1: 평가단가 | L1: 평가금액 | M1: 평가손익금액 | N1: 채권이자 | O1: 당기미수이자 | P1: 전기미수이자 | Q1: 경과이자 | R1: 단가구분 | S1: 법인세예수금 | T1: 법인세 | U1: 주민세 | V1: 듀레이션 | W1: 수정듀레이션 | X1: 컨백시티 | Y1: 신용등급 | Z1: KBP단가 | AA1: KBP등급 | AB1: KIS단가 | AC1: KIS등급 | AD1: NICE단가 | AE1: NICE등급 | AF1: 회계구분 | AG1: 이자율구분 | AH1: 매수일자 | AI1: ESG구분 | AJ1: 표준종목코드 | AK1: 발행방법 | AL1: 권리구분
A2: 7120 | B2: 46121 | C2: 금융채 | D2: B000014EB | E2: 신한은행28-11-이-1.5-B | F2: 46150 | G2: 3.24 | H2: 10000000 | I2: 10014456522 | J2: 2.754 | K2: 10059 | L2: 10059000000 | M2: -10973375 | N2: 55516853 | O2: 55516853 | P2: 0 | Q2: 0 | S2: 0 | T2: 7772350 | U2: 777230 | V2: 0.079733333 | W2: 0.079166667 | X2: 0.021466667 | Y2: AAA | Z2: 10059.28 | AA2: AAA | AB2: 10059.19 | AC2: AAA | AD2: 10059.15 | AE2: AAA | AF2: 금융채 | AG2: 일반채권 | AI2: 해당없음 | AJ2: KR6000014EB1 | AK2: 공모채간접발행
A3: 7120 | B3: 46121 | C3: 금융채 | D3: B000016F8 | E3: 신한은행29-08-이-1.25-B | F3: 46353 | G3: 2.53 | H3: 30000000 | I3: 29921812500 | J3: 2.906 | K3: 10006 | L3: 30018000000 | M3: 6642557 | N3: 89544943 | O3: 89544943 | P3: 0 | Q3: 0 | S3: 0 | T3: 12536290 | U3: 1253620 | V3: 0.6284 | W3: 0.62386667 | X3: 0.54083333 | Y3: AAA | Z3: 10006.57 | AA3: AAA | AB3: 10006.38 | AC3: AAA | AD3: 10005.76 | AE3: AAA | AF3: 금융채 | AG3: 일반채권 | AI3: 해당없음 | AJ3: KR6000016F83 | AK3: 공모채간접발행
A4: 7120 | B4: 46121 | C4: 금융채 | D4: B000033EA | E4: 우리은행28-10-이표1.5-갑-18 | F4: 46130 | G4: 3.17 | H4: 10000000 | I4: 10010394022 | J4: 2.743 | K4: 10073 | L4: 10073000000 | M4: -9599577 | N4: 72205555 | O4: 72205555 | P4: 0 | Q4: 0 | S4: 0 | T4: 10108770 | U4: 1010870 | V4: 0.0232 | W4: 0.023033333 | X4: 0.0046 | Y4: AAA | Z4: 10073.1 | AA4: AAA | AB4: 10073.12 | AC4: AAA | AD4: 10073.09 | AE4: AAA | AF4: 금융채 | AG4: 일반채권 | AI4: 해당없음 | AJ4: KR6000033EA3 | AK4: 공모채간접발행
A5: 7120 | B5: 46121 | C5: 금융채 | D5: B060006F7 | E5: 국민은행4507할인일10M-30 | F5: 46172 | G5: 2.49 | H5: 20000000 | I5: 19558520548 | J5: 2.767 | K5: 9962 | L5: 19924000000 | M5: 18926028 | N5: 346553424 | O5: 135073972 | P5: 141895891 | Q5: 69583561 | S5: 0 | T5: 38775780 | U5: 3877570 | V5: 0.1379 | W5: 0.13526667 | X5: 0.11183333 | Y5: AAA | Z5: 9962.37 | AA5: AAA | AB5: 9962.19 | AC5: AAA | AD5: 9962.13 | AE5: AAA | AF5: 금융채 | AG5: 일반채권 | AI5: 해당없음 | AJ5: KR6060006F71 | AK5: 공모채간접발행
A6: 7120 | B6: 46121 | C6: 금융채 | D6: E10206GEB | E6: 산업금융채권24신이0200-1112-2 | F6: 46338 | G6: 3.15 | H6: 10000000 | I6: 10030173914 | J6: 2.867 | K6: 10066 | L6: 10066000000 | M6: -14641329 | N6: 50467415 | O6: 50467415 | P6: 0 | Q6: 0 | S6: 0 | T6: 7065430 | U6: 706540 | V6: 0.58513333 | W6: 0.58096667 | X6: 0.47936667 | Y6: AAA | Z6: 10067.04 | AA6: AAA | AB6: 10067.04 | AC6: AAA | AD6: 10066.33 | AE6: AAA | AF6: 특수채 | AG6: 일반채권 | AI6: 해당없음 | AJ6: KR310206GEB3 | AK6: 공모채간접발행
A7: 7120 | B7: 46121 | C7: 금융채 | D7: E10209GE4 | E7: 산업금융채권24신이0200-0429-4 | F7: 46141 | G7: 3.68 | H7: 30000000 | I7: 30084000000 | J7: 2.733 | K7: 10077 | L7: 30231000000 | M7: -70733333 | N7: 217733333 | O7: 217733333 | P7: 0 | Q7: 0 | S7: 0 | T7: 30482660 | U7: 3048260 | V7: 0.053833333 | W7: 0.053433333 | X7: 0.0127 | Y7: AAA | Z7: 10077.51 | AA7: AAA | AB7: 10077.45 | AC7: AAA | AD7: 10077.42 | AE7: AAA | AF7: 특수채 | AG7: 일반채권 | AI7: 해당없음 | AJ7: KR310209GE45 | AK7: 공모채간접발행
A8: 7120 | B8: 46121 | C8: 금융채 | D8: E10503AFA | E8: 중소기업은행(신)2510할1A-16 | F8: 46311 | G8: 2.47 | H8: 20000000 | I8: 19463786302 | J8: 2.845 | K8: 9854 | L8: 19708000000 | M8: 6010959 | N8: 238202739 | O8: 133989041 | P8: 98800000 | Q8: 5413698 | S8: 0 | T8: 32590460 | U8: 3259040 | V8: 0.5187 | W8: 0.50663333 | X8: 0.67073333 | Y8: AAA | Z8: 9855.27 | AA8: AAA | AB8: 9854.87 | AC8: AAA | AD8: 9854.21 | AE8: AAA | AF8: 특수채 | AG8: 일반채권 | AI8: 해당없음 | AJ8: KR310503AFA5 | AK8: 공모채간접발행
A9: 7120 | B9: 46121 | C9: 금융채 | D9: E10504AFA | E9: 중소기업은행(신)2510할1A-17 | F9: 46312 | G9: 2.48 | H9: 40000000 | I9: 38925446576 | J9: 2.846 | K9: 9853 | L9: 39412000000 | M9: 10936986 | N9: 475616438 | O9: 269063014 | P9: 206553424 | Q9: 0 | S9: 0 | T9: 66586300 | U9: 6658630 | V9: 0.52143333 | W9: 0.50933333 | X9: 0.676 | Y9: AAA | Z9: 9854.46 | AA9: AAA | AB9: 9854.06 | AC9: AAA | AD9: 9853.4 | AE9: AAA | AF9: 특수채 | AG9: 일반채권 | AI9: 해당없음 | AJ9: KR310504AFA3 | AK9: 공모채간접발행
A10: 7120 | B10: 46121 | C10: 금융채 | D10: E10511GEA | E10: 중소기업은행(신)2410이1.5A-21 | F10: 46133 | G10: 3.17 | H10: 10000000 | I10: 10010978261 | J10: 2.729 | K10: 10070 | L10: 10070000000 | M10: -10542149 | N10: 69563888 | O10: 69563888 | P10: 0 | Q10: 0 | S10: 0 | T10: 9738940 | U10: 973890 | V10: 0.031533333 | W10: 0.0313 | X10: 0.0065666666 | Y10: AAA | Z10: 10070.87 | AA10: AAA | AB10: 10070.84 | AC10: AAA | AD10: 10070.83 | AE10: AAA | AF10: 특수채 | AG10: 일반채권 | AI10: 해당없음 | AJ10: KR310511GEA8 | AK10: 공모채간접발행
A11: 7120 | B11: 46121 | C11: 금융채 | D11: E81003GEB | E11: 농업금융채권(은행)2024-11이2Y-B | F11: 46340 | G11: 3.25 | H11: 30000000 | I11: 30106826087 | J11: 2.896 | K11: 10070 | L11: 30210000000 | M11: -47458109 | N11: 150632022 | O11: 150632022 | P11: 0 | Q11: 0 | S11: 0 | T11: 21088480 | U11: 2108840 | V11: 0.59056667 | W11: 0.5863 | X11: 0.4869 | Y11: AAA | Z11: 10071.19 | AA11: AAA | AB11: 10071.02 | AC11: AAA | AD11: 10070.43 | AE11: AAA | AF11: 금융채 | AG11: 일반채권 | AI11: 해당없음 | AJ11: KR381003GEB8 | AK11: 공모채간접발행

Sheet 7120(외화)_K8224
A1: 펀드코드 | B1: 종목코드 | C1: 종목명 | D1: 매수일자 | E1: 액면수량 | F1: 담보수량 | G1: 양도담보수량 | H1: REPO수량 | I1: 장부가 | J1: 원화장부가 | K1: 평가기준가 | L1: 경과이자 | M1: 미수이자 | N1: 외화RP수시 | O1: 외화RP약정 | P1: 외화RP협의 | Q1: ESG채권구분
A2: 7120 | B2: US500630DF23 | C2: KDB 0.4 06/19/24 | D2: 44483 | E2: 2000000 | F2: 0 | G2: 0 | H2: 0 | I2: 1875240 | J2: 2376491652 | K2: 95.4237 | L2: 0 | M2: 244.44 | N2: 0 | O2: 0 | P2: 0 | Q2: 녹색채권
A3: 7120 | B3: US65540KAF21 | C3: NACF 0 7/8 07/28/24 | D3: 44481 | E3: 3000000 | F3: 0 | G3: 0 | H3: 0 | I3: 2805030 | J3: 3554814519 | K3: 95.366 | L3: 0 | M3: 0 | N3: 0 | O3: 0 | P3: 0 | Q3: 사회적채권
A27: ,합 계,,,,,000000000005000000,000000000000000000,000000000000000000,000000000000000000,00000004680270.0000,000000005931306171,,,,000000000000000000,000000000000000000,000000000000000000,

Sheet 9988
A1: 펀드코드 | B1: 평가일자 | C1: 채권종류 | D1: 종목코드 | E1: 종목명 | F1: 만기일자 | G1: 표면이율 | H1: 수량 | I1: 장부금액 | J1: 평가수익율 | K1: 평가단가 | L1: 평가금액 | M1: 평가손익금액 | N1: 채권이자 | O1: 당기미수이자 | P1: 전기미수이자 | Q1: 경과이자 | R1: 단가구분 | S1: 법인세예수금 | T1: 법인세 | U1: 주민세 | V1: 듀레이션 | W1: 수정듀레이션 | X1: 컨백시티 | Y1: 신용등급 | Z1: KBP단가 | AA1: KBP등급 | AB1: KIS단가 | AC1: KIS등급 | AD1: NICE단가 | AE1: NICE등급 | AF1: 회계구분 | AG1: 이자율구분 | AH1: 매수일자 | AI1: ESG구분 | AJ1: 표준종목코드 | AK1: 발행방법 | AL1: 권리구분
A2: 9988 | B2: 46121 | C2: 국채 | D2: C03502GEC | E2: 국고채권03000-3412(24-13) | F2: 49288 | G2: 3 | H2: 300000000 | I2: 306975474829 | J2: 3.65 | K2: 9619 | L2: 288570000000 | M2: -21397233066 | N2: 2991758237 | O2: 2991758237 | P2: 0 | Q2: 0 | S2: 0 | T2: 418846100 | U2: 41884560 | V2: 7.5896333 | W2: 7.4536 | X2: 64.302833 | Z2: 9619.8 | AB2: 9618.37 | AD2: 9619.8 | AF2: 국채 | AG2: 일반채권 | AI2: 해당없음 | AJ2: KR103502GEC4 | AK2: 공모채직접발행

Sheet 8226
A1: 평가일자 | B1: 기관구분 | C1: 펀드 | D1: 펀드명 | E1: 종목코드 | F1: 종목명 | G1: 매수일자 | H1: 만기일자 | I1: 통화 | J1: 수량 | K1: 적용환율 | L1: 수익율 | M1: 외화장부단가 | N1: 외화장부금액 | O1: 원화장부금액 | P1: 외화평가단가 | Q1: 외화평가금액 | R1: 원화평가금액 | S1: 외화평가손익 | T1: 원화평가손익 | U1: 외화환산손익 | V1: 원화손익합계 | W1: 외화전체이자 | X1: 원화전체이자 | Y1: 외화당기채권이자 | Z1: 원화당기채권이자 | AA1: 외화미수이자 | AB1: 원화미수이자 | AC1: 미수이자환차손익 | AD1: 외화경과이자 | AE1: 원화경과이자 | AF1: 경과이자환차손익 | AG1: 발행기관코드 | AH1: 발행기관명 | AI1: 국가코드 | AJ1: 국가명 | AK1: 권리구분
A2: 45023 | B2: '01 평균 | C2: 7120 | D2: 외화RP펀드 | E2: US500630DF23 | F2: KDB 0.4 06/19/24 | G2: 44483 | H2: 45463 | I2: USD | J2: 2000000 | K2: 1318.7 | L2: 4.355 | M2: 93.762 | N2: 1875240 | O2: 2376491652 | P2: 95.424 | Q2: 1908480 | R2: 2516712576 | S2: 33240 | T2: 43833588 | U2: 96387336 | V2: 140220924 | W2: 2400 | X2: 3164880 | Y2: 2155.56 | Z2: 2842537 | AA2: 244.44 | AB2: 322343 | AC2: 12565 | AD2: 0 | AE2: 0 | AF2: 0 | AG2: B312094 | AH2: 한국산업은행 | AI2: 410 | AJ2: 대한민국
A3: 45023 | B3: '01 평균 | C3: 7120 | D3: 외화RP펀드 | E3: US65540KAF21 | F3: NACF 0 7/8 07/28/24 | G3: 44481 | H3: 45501 | I3: USD | J3: 3000000 | K3: 1318.7 | L3: 4.563 | M3: 93.501 | N3: 2805030 | O3: 3554814519 | P3: 95.366 | Q3: 2860980 | R3: 3772774326 | S3: 55950 | T3: 73781265 | U3: 144178542 | V3: 217959807 | W3: 5031.25 | X3: 6634709 | Y3: 5031.25 | Z3: 6634709 | AA3: 0 | AB3: 0 | AC3: 0 | AD3: 0 | AE3: 0 | AF3: 0 | AG3: R082974 | AH3: 농협은행 | AI3: 410 | AJ3: 대한민국

Sheet 심포니
A1: No | B1: 북 | C1: 북Id | D1: 번들Id | E1: 거래구분 | F1: 북상태 | G1: 기준 명목잔액 통화코드 | H1: 기준 명목잔액 | I1: 명목잔액 통화코드 | J1: 명목잔액 | K1: 2nd명목잔액 통화코드 | L1: 2nd명목잔액 | M1: 북코드 | N1: 북유형 | O1: 자산/부채 | P1: 기초자산 | Q1: 북 기준통화 | R1: 통화 | S1: 취득금액 | T1: 장부잔액 | U1: 기준장부금액 | V1: 평가금액 | W1: 평가금액(M) | X1: 평가금액(First) | Y1: 수취경과이자 | Z1: 지급경과이자 | AA1: MTM평가구분 | AB1: 신용위험충당금 | AC1: 신용위험충당금 | AD1: 신용위험충당금 | AE1: 이연거래손익 | AF1: 이연거래손익 | AG1: 이연거래손익 | AH1: 이연거래손익 | AI1: 이연거래손익 | AJ1: 이연거래손익 | AK1: 이연거래손익 | AL1: 이연수수료총손익 | AM1: 이연수수료총손익 | AN1: 이연수수료총손익 | AO1: 이연수수료총손익 | AP1: 이연수수료총손익 | AQ1: 이연수수료총손익 | AR1: 이연수수료총손익
A2: No | B2: 북 | C2: 북Id | D2: 번들Id | E2: 거래구분 | F2: 북상태 | G2: 기준 명목잔액 통화코드 | H2: 기준 명목잔액 | I2: 명목잔액 통화코드 | J2: 명목잔액 | K2: 2nd명목잔액 통화코드 | L2: 2nd명목잔액 | M2: 북코드 | N2: 북유형 | O2: 자산/부채 | P2: 기초자산 | Q2: 북 기준통화 | R2: 통화 | S2: 취득금액 | T2: 장부잔액 | U2: 기준장부금액 | V2: 평가금액 | W2: 평가금액(M) | X2: 평가금액(First) | Y2: 수취경과이자 | Z2: 지급경과이자 | AA2: MTM평가구분 | AB2: 기준 | AC2: 잔액 | AD2: 평가 | AE2: 취득 | AF2: 기준 | AG2: 잔액 | AH2: 실현 | AI2: 상각액 (누적) | AJ2: 상각액 (일) | AK2: 잔액 - 상각액(누적) | AL2: 취득 | AM2: 기준 | AN2: 잔액 | AO2: 실현 | AP2: 상각액 (누적) | AQ2: 상각액 (일) | AR2: 잔액 - 상각액(누적)
A3: No | B3: 북 | C3: 북Id | D3: 번들Id | E3: 거래구분 | F3: 북상태 | G3: 기준 명목잔액 통화코드 | H3: 기준 명목잔액 | I3: 명목잔액 통화코드 | J3: 명목잔액 | K3: 2nd명목잔액 통화코드 | L3: 2nd명목잔액 | M3: 북코드 | N3: 북유형 | O3: 자산/부채 | P3: 기초자산 | Q3: 북 기준통화 | R3: 통화 | S3: 취득금액 | T3: 장부잔액 | U3: 기준장부금액 | V3: 평가금액 | W3: 평가금액(M) | X3: 평가금액(First) | Y3: 수취경과이자 | Z3: 지급경과이자 | AA3: MTM평가구분 | AB3: 기준 | AC3: 잔액 | AD3: 평가 | AE3: 취득 | AF3: 기준 | AG3: 잔액 | AH3: 실현 | AI3: 상각액 (누적) | AJ3: 상각액 (일) | AK3: 잔액 - 상각액(누적) | AL3: 취득 | AM3: 기준 | AN3: 잔액 | AO3: 실현 | AP3: 상각액 (누적) | AQ3: 상각액 (일) | AR3: 잔액 - 상각액(누적)
A4: 1 | B4: IRS2682-4 | C4: 529775 | E4: 외부거래 | F4: Book | G4: KRW | H4: 10000000000 | I4: KRW | J4: 10000000000 | K4: KRW | L4: 10000000000 | M4: I260405A200P | N4: 파생상품(이자율/스왑) | O4: 부채 | P4: CD 91D,Fixed | Q4: KRW | R4: KRW | S4: 0 | T4: 0 | U4: 0 | V4: -17484086 | W4: -17484086 | X4: -867022 | Y4: 1545205.5 | Z4: 1882191.8 | AA4: 내부 시스템 | AB4: 0 | AC4: 0 | AE4: 0 | AF4: 0 | AG4: 0 | AH4: 0 | AI4: 0 | AK4: 0 | AL4: 0 | AM4: 0 | AN4: 0 | AO4: 0 | AP4: 0 | AR4: 0

Sheet 국채선물
A1: 펀드번호 | B1: 펀드종류 | C1: KTB | D1: LKTB | E1: 합계 | F1: KTB환산 | G1: LKTB환산 | H1: 환산합
A2: 8001 | B2: =VLOOKUP(A2,[1]펀드종류!$A$2:$B$218,2,FALSE) -> PD | D2: -80 | E2: =ABS(C2)+ABS(D2) -> 80 | F2: =C2*$C$27*$C$28/100 -> 0 | G2: =D2*$D$27*$D$28/100 -> -707.39434 | H2: =F2+G2 -> -707.39434
A3: 8002 | B3: =VLOOKUP(A3,[1]펀드종류!$A$2:$B$218,2,FALSE) -> 리테일 | E3: =ABS(C3)+ABS(D3) -> 0 | F3: =C3*$C$27*$C$28/100 -> 0 | G3: =D3*$D$27*$D$28/100 -> 0 | H3: =F3+G3 -> 0
A4: 8003 | B4: =VLOOKUP(A4,[1]펀드종류!$A$2:$B$218,2,FALSE) -> 중개 | E4: =ABS(C4)+ABS(D4) -> 0 | F4: =C4*$C$27*$C$28/100 -> 0 | G4: =D4*$D$27*$D$28/100 -> 0 | H4: =F4+G4 -> 0
A5: 8004 | B5: =VLOOKUP(A5,[1]펀드종류!$A$2:$B$218,2,FALSE) -> 중개 | E5: =ABS(C5)+ABS(D5) -> 0 | F5: =C5*$C$27*$C$28/100 -> 0 | G5: =D5*$D$27*$D$28/100 -> 0 | H5: =F5+G5 -> 0
A6: 8005 | B6: =VLOOKUP(A6,[1]펀드종류!$A$2:$B$218,2,FALSE) -> 운용 | E6: =ABS(C6)+ABS(D6) -> 0 | F6: =C6*$C$27*$C$28/100 -> 0 | G6: =D6*$D$27*$D$28/100 -> 0 | H6: =F6+G6 -> 0
A7: 8006 | B7: =VLOOKUP(A7,[1]펀드종류!$A$2:$B$218,2,FALSE) -> 운용 | E7: =ABS(C7)+ABS(D7) -> 0 | F7: =C7*$C$27*$C$28/100 -> 0 | G7: =D7*$D$27*$D$28/100 -> 0 | H7: =F7+G7 -> 0
A8: 8007 | B8: =VLOOKUP(A8,[1]펀드종류!$A$2:$B$218,2,FALSE) -> 운용 | E8: =ABS(C8)+ABS(D8) -> 0 | F8: =C8*$C$27*$C$28/100 -> 0 | G8: =D8*$D$27*$D$28/100 -> 0 | H8: =F8+G8 -> 0
A9: 8008 | B9: =VLOOKUP(A9,[1]펀드종류!$A$2:$B$218,2,FALSE) -> 운용2 | D9: 30 | E9: =ABS(C9)+ABS(D9) -> 30 | F9: =C9*$C$27*$C$28/100 -> 0 | G9: =D9*$D$27*$D$28/100 -> 265.27288 | H9: =F9+G9 -> 265.27288
A10: 8009 | B10: =VLOOKUP(A10,[1]펀드종류!$A$2:$B$218,2,FALSE) -> 운용 | E10: =ABS(C10)+ABS(D10) -> 0 | F10: =C10*$C$27*$C$28/100 -> 0 | G10: =D10*$D$27*$D$28/100 -> 0 | H10: =F10+G10 -> 0
A11: 8010 | B11: =VLOOKUP(A11,[1]펀드종류!$A$2:$B$218,2,FALSE) -> RP | E11: =ABS(C11)+ABS(D11) -> 0 | F11: =C11*$C$27*$C$28/100 -> 0 | G11: =D11*$D$27*$D$28/100 -> 0 | H11: =F11+G11 -> 0
A12: 8011 | B12: =VLOOKUP(A12,[1]펀드종류!$A$2:$B$218,2,FALSE) -> 운용 | C12: 300 | E12: =ABS(C12)+ABS(D12) -> 300 | F12: =C12*$C$27*$C$28/100 -> 870.82088 | G12: =D12*$D$27*$D$28/100 -> 0 | H12: =F12+G12 -> 870.82088
A13: 8012 | B13: =VLOOKUP(A13,[1]펀드종류!$A$2:$B$218,2,FALSE) -> 운용 | E13: =ABS(C13)+ABS(D13) -> 0 | F13: =C13*$C$27*$C$28/100 -> 0 | G13: =D13*$D$27*$D$28/100 -> 0 | H13: =F13+G13 -> 0
A14: 8013 | B14: =VLOOKUP(A14,[1]펀드종류!$A$2:$B$218,2,FALSE) -> CMA | E14: =ABS(C14)+ABS(D14) -> 0 | F14: =C14*$C$27*$C$28/100 -> 0 | G14: =D14*$D$27*$D$28/100 -> 0 | H14: =F14+G14 -> 0
A15: 8014 | B15: =VLOOKUP(A15,[1]펀드종류!$A$2:$B$218,2,FALSE) -> 리테일 | E15: =ABS(C15)+ABS(D15) -> 0 | F15: =C15*$C$27*$C$28/100 -> 0 | G15: =D15*$D$27*$D$28/100 -> 0 | H15: =F15+G15 -> 0
A16: 8015 | B16: =VLOOKUP(A16,[1]펀드종류!$A$2:$B$218,2,FALSE) -> 운용 | E16: =ABS(C16)+ABS(D16) -> 0 | F16: =C16*$C$27*$C$28/100 -> 0 | G16: =D16*$D$27*$D$28/100 -> 0 | H16: =F16+G16 -> 0
A17: 8016 | B17: =VLOOKUP(A17,[1]펀드종류!$A$2:$B$218,2,FALSE) -> 운용 | C17: -1500 | D17: 900 | E17: =ABS(C17)+ABS(D17) -> 2400 | F17: =C17*$C$27*$C$28/100 -> -4354.1044 | G17: =D17*$D$27*$D$28/100 -> 7958.1863 | H17: =F17+G17 -> 3604.0819
A18: 8017 | B18: =VLOOKUP(A18,[1]펀드종류!$A$2:$B$218,2,FALSE) -> 운용 | E18: =ABS(C18)+ABS(D18) -> 0 | F18: =C18*$C$27*$C$28/100 -> 0 | G18: =D18*$D$27*$D$28/100 -> 0 | H18: =F18+G18 -> 0
A19: 8018 | E19: =ABS(C19)+ABS(D19) -> 0 | F19: =C19*$C$27*$C$28/100 -> 0 | G19: =D19*$D$27*$D$28/100 -> 0 | H19: =F19+G19 -> 0
A20: 8019 | B20: =VLOOKUP(A20,[1]펀드종류!$A$2:$B$218,2,FALSE) -> 운용 | E20: =ABS(C20)+ABS(D20) -> 0 | F20: =C20*$C$27*$C$28/100 -> 0 | G20: =D20*$D$27*$D$28/100 -> 0 | H20: =F20+G20 -> 0
A21: 8020 | E21: =ABS(C21)+ABS(D21) -> 0 | F21: =C21*$C$27*$C$28/100 -> 0 | G21: =D21*$D$27*$D$28/100 -> 0 | H21: =F21+G21 -> 0
A22: 8021 | B22: =VLOOKUP(A22,[1]펀드종류!$A$2:$B$218,2,FALSE) -> 운용 | E22: =ABS(C22)+ABS(D22) -> 0 | F22: =C22*$C$27*$C$28/100 -> 0 | G22: =D22*$D$27*$D$28/100 -> 0 | H22: =F22+G22 -> 0
A23: 8022 | B23: =VLOOKUP(A23,[1]펀드종류!$A$2:$B$218,2,FALSE) -> 운용 | E23: =ABS(C23)+ABS(D23) -> 0 | F23: =C23*$C$27*$C$28/100 -> 0 | G23: =D23*$D$27*$D$28/100 -> 0 | H23: =F23+G23 -> 0
A24: 8033 | B24: 중개 | E24: =ABS(C24)+ABS(D24) -> 0 | F24: =C24*$C$27*$C$28/100 -> 0 | G24: =D24*$D$27*$D$28/100 -> 0 | H24: =F24+G24 -> 0
A25: 9988 | B25: 운용 | E25: =ABS(C25)+ABS(D25) -> 0 | F25: =C25*$C$27*$C$28/100 -> 0 | G25: =D25*$D$27*$D$28/100 -> 0 | H25: =F25+G25 -> 0
A26: 7120 | B26: RP | E26: =ABS(C26)+ABS(D26) -> 0 | F26: =C26*$C$27*$C$28/100 -> 0 | G26: =D26*$D$27*$D$28/100 -> 0 | H26: =F26+G26 -> 0
A27: 듀레이션 | C27: 2.7796 | D27: 7.964 | E27: 체크3823 | F27: 인포3650
A28: 선물가격 | C28: 104.43 | D28: 111.03
C30: =SUM(C2:C26) -> -1200 | D30: =SUM(D2:D26) -> 850 | E30: =SUM(C30:D30) -> -350

Sheet 일일위험관리(출력)
A1: 4. 채권운용부 일일 위험 및 한도관리 (전일체결기준)
H2: 46120
H3: (단위: 억, 년, %)
A4: 1. 규제자본(NCR) 관리 | F4: 2. 포지션한도관리
A6: 구분 | C6: 시장 | D6: 신용 | F6: 구분 | G6: 포지션 | H6: 한도(억) | I6: 소진율
A7: 채권운용 | B7: 포지션 | C7: 170.27717 | D7: 0 | F7: 채권운용 | G7: 5152.6665 | H7: 8000 | I7: 0.64408332
B8: 한도 | C8: 240 | D8: 33 | F8: RP운용 | G8: 19000 | H8: 19000 | I8: 1
B9: 소진율 | C9: 0.7094882 | D9: 0 | F9: B/F운용 | G9: 1300 | H9: 8000 | I9: 0.1625
A10: RP운용 | B10: 포지션 | C10: 107.44833 | D10: 42.395575 | G10: 25452.667 | H10: 35000 | I10: 0.72721904
B11: 한도 | C11: 182 | D11: 75
B12: 소진율 | C12: 0.59037542 | D12: 0.56527433 | F12: 3. 채권운용 현물한도관리
A13: B/F운용 | B13: 포지션 | C13: 0.68872011 | D13: 0
B14: 한도 | C14: 18 | D14: 12 | F14: 구분 | G14: 포지션 | H14: 한도(억) | I14: 소진율
B15: 소진율 | C15: 0.038262228 | D15: 0 | F15: 채권운용 | G15: 3902.6665 | H15: 8000 | I15: 0.48783332
A17: 4. 리스크자본 관리 | F17: 5. DVO1
A19: 구분 | C19: 시장 | D19: 신용 | F19: 구분 | G19: Book | H19: DVO1(억)
A20: 채권운용 | B20: 포지션 | C20: 290.18143 | D20: 0 | F20: 채권운용 | G20: 채권운용 | H20: 0.57511777
B21: 한도 | C21: 400 | D21: 33 | G21: 매도가능 | H21: 2.1553356
B22: 소진율 | C22: 0.72545357 | D22: 0 | F22: 합계 | G22: 2.7304534
A23: 외화채권운용 | B23: 포지션 | C23: 0 | D23: #REF!
B24: 한도 | C24: 0 | D24: 0
B25: 소진율 | C25: #DIV/0! | D25: #REF!
A26: RP운용 | B26: 포지션 | C26: 29.787862 | D26: 19.538869 | F26: RP운용 | G26: 일반RP | H26: 0.51977563
B27: 한도 | C27: 143 | D27: 112 | G27: CMA | H27: 0.2683218
B28: 소진율 | C28: 0.20830672 | D28: 0.17445419 | G28: 증금RP | H28: 0.15579585
A29: B/F운용 | B29: 포지션 | C29: 2.327978 | D29: 0.38113741 | G29: 외화RP | H29: 0.079675721
B30: 한도 | C30: 18 | D30: 12 | F30: 합계 | G30: 1.023569
B31: 소진율 | C31: 0.12933211 | D31: 0.031761451 | F31: 부서합계* | G31: 3.7540224
A32: 주식운용 | B32: 포지션 | C32: 0
B33: 한도 | C33: 61
B34: 소진율 | C34: 0
A35: 합 계 | B35: 포지션 | C35: #REF! | D35: #REF!
B36: 한도 | C36: #REF! | D36: #REF!
B37: 소진율 | C37: #REF! | D37: #REF!
F38: * B/F제외
A39: 6. 듀레이션관리
A41: 구분 | B41: 포지션 | C41: 한도 | D41: 소진율 | E41: 판정 | F41: 비고
A42: 채권운용 | B42: 27304.534 | C42: 45,000억 | D42: 0.60676741 | E42: OK | F42: 총량기준 (3,000억*10년 +5,000억*3년) | P42: =9000-P43 -> 6000 | Q42: 3
A43: 부서전체 | B43: 2.062348 | C43: - | D43: - | E43: - | F43: 듀레이션 기준 | P43: 3000 | Q43: 10
A44: RP운용(CMA, 증금, 외화RP포함) | B44: 0.53747105 | C44: 1년 | D44: 0.53747105 | E44: OK | Q44: =SUMPRODUCT(P42:P43,Q42:Q43) -> 48000
...

Sheet Sheet9
